#### 异常处理

go语言没有类似于其他语言的异常处理机制，虽然可以使用defer、panic、recover模拟，但是官网并不推荐，

go语言希望开发将错误处理视为正常开发必须实现的环节，正确的处理每一个可能发生的错误函数，同时，go语言使用返回值返回错误的机制。

#### panic

引发panic的情况:
	程序主动调用panic函数
	程序运行异常，由运行时检测抛出

* **发生panic后，程序会从调用panic的函数位置或者发生panic的地方立即返回，所以尽量不要在主程序中执行panic，会导致主程序退出**，逐层向上执行函数defer语句，然后逐层打印函数调用堆栈，直到被recover捕获或者运行到最外层函数而退出。
  如果连续多个panic抛出异常，只会一个被执行，
  如果是多个defer中抛出异常,只有第一个抛出的异常的defer会被捕获。
* panic()的参数是一个空接口类型interface{}，所以任意类型的变量都可以传递给panic(),
* panic不但可以在函数正常流程中抛出，在defer逻辑里面也可以再次调用panic或者抛出panic,defer中panic能够被后续执行的defer捕获，

程序发生异常后，是按照panic注册的语句逆序执行的，所以defer语句必须在发生异常的语句前面才会生效

```go
package main

import (
	"fmt"
)

func main()  {
	defer func() {
		if err:=recover();err!=nil{
			fmt.Println(err)
		}
	}()
	i :=10
	d := 0
	c:=i/d

	fmt.Println(c)
    // 如果写在这是捕获不到异常的。
	//defer func() {
	//	if err:=recover();err!=nil{
	//		fmt.Println(err)
	//	}
	//}()
}
```

#### recover

recover用来捕获panic,阻止panic继续向上传递，recover()只能和defer一起使用。只有在defer后面的函数体内被直接调用才能捕获panice的异常， 否则返回nil，继续向外传递。

```go
package main

import (
	"fmt"
)

func main()  {
	defer recover()
	defer fmt.Print(recover())
	defer func() {
		func(){
			fmt.Println("defer inner 1")
			recover()
		}()
	}()

	defer func() {
		fmt.Println("defer inner 2")
		recover()
	}()
	panic("xxxxx")
}
```

init 函数引发的panic 只能在init函数中捕获，在main函数中无法被捕获，init函数先于main函数执行。函数并不能捕获goroutine中的异常，

#### 多个panic抛出异常

如果连续多个panic抛出异常，只会一个被执行，

```go
package main

import (
	"fmt"
)

func main()  {
	defer func() {
		if err:=recover();err !=nil{
			fmt.Println("defer inner")
		}
	}()

	panic("xxxxx") // 只有这个会被捕获。后面的语句不会被执行
	panic("11111")
	panic("222222")
	panic("333333")

}
```

如果是多个defer中抛出异常,只有第一个抛出的异常的defer会被捕获。

```go
package main

import (
	"fmt"
)

func main()  {
	defer func() {
		if err:=recover();err !=nil{
			fmt.Println("defer inner")
		}
	}()
	defer fmt.Println(recover())

	//这个嵌套两层的捕获是无效的。
	defer func() {
		func(){
			if err:=recover();err !=nil{
				fmt.Println("defer inner1")
			}
		}()
	}()
	defer func() {
		if err:=recover();err !=nil{
			fmt.Println("defer inner2")
			fmt.Println(err)
		}
	}()
	defer panic("xxxxx") // 只有这个会被捕获。后面的语句不会被执行
	defer panic("11111")
	defer panic("222222")

}
```

#### 正常用法

```go
package main

import "fmt"

func test()  {
	defer func() {
		if err:=recover();err!=nil{
			fmt.Println(err)
		}
	}()
	c:=0
	d:=10
	f:=d/c
	fmt.Println(f)
}

func main()  {
	test()
	fmt.Println("xxxx")
}
```

#### goroutine 中进行异常捕获

防止某个进程出错造成这个程序出错，

```go
package main

import (
	"fmt"
	"time"
)


func test()  {
	// 进行异常捕获,虽然主程序有异常,但是主程序没有不会退出
	defer func() {
		if err:=recover();err!=nil{
			fmt.Println(err)
		}
	}()
	var a map[string]string
	// 如下没有对这个错误进行捕获会造成整个程序的中断
	a["xx"]="10"
}


func main()  {
	go test()
	for {
		time.Sleep(1*time.Second)
		fmt.Println("主程序正在运行")
	}
}
```





#### error

go 语言的典型错误处理方式是将error作为函数最后一个返回值，在函数调用的时候通过检测返回的error值是否为空来进行错误处理，一般情况是将error当做最后一个返回值

error实际是一个接口,只要是实现这个接口就可以

```go
type error interface {
    Error() string
}
```

定义错误

```go
package main

import (
	"errors"
	"fmt"
)

var errNotFond error = errors.New("Not fond error ")

func main()  {
	fmt.Printf("error: %v",errNotFond)
}
```

自定义错误，只要是实现了错误Error接口即可

```go
package main

import (
	"fmt"
	"os"
	"time"
)

type PathError struct {
	path string
	op string
	createTime string
	message string
}

func (p *PathError)Error() string  {
	return fmt.Sprintf("path:%s op:%s createTime:%s message:%s", p.path,p.op,p.createTime,p.message)
}

func Open(filename string) error  {
	file,err :=os.Open(filename)
	if err!=nil{
		return &PathError{
			path:       filename,
			op:         "read",
			createTime: fmt.Sprintf("%v",time.Now()),
			message:    err.Error(),
		}
	}
	defer file.Close()
	return nil
}

func main()  {
	err:=Open("xxxxx")
	// 对我们定义的错误类型进行自定义的判断可以使用,也可以不使用
	switch v:=err.(type) {
	case *PathError:
		fmt.Println("file path error",v)
	default:
		fmt.Println(err)
	}
}
```

> **对于错误的处理我们可以自定错误，也可以直接使用errors.New,主要是看需求，一般情况下使用errors.New就可以**

